Workbook

Sheet 00_Leia_Primeiro
A1: Caderno de Testes — SignallQ Android
A2: Execução assistida por IA • Pixel 10 AVD • design To-Be + funcionalidade do código atual • bugs no GitHub somente após reteste
A4: REGRA ZERO | B4: Ligue os logs ANTES de abrir o app. Se logcat não estiver ativo, o teste não começou.
A5: Fonte de design | B5: C:\Users\luizg\Documents\7Agents\Claude Design\SignallQ Design System — telas To-Be em tobe/ e componentes _preview/_ds_bundle.js
A6: Fonte de código | B6: https://github.com/gmmattey/linka-android — main — inspeção em 15/07/2026; registrar o HEAD real antes da execução
A7: Pacote Android | B7: io.signallq.app
A8: Alvo recomendado | B8: Pixel 10 AVD, API 36; executar ao menos navegação por gestos e por 3 botões.
A9: Ordem recomendada | B9: 02 Entrada → 03 Início → 04 Velocidade → 05 Sinal → 06 Histórico → 07 Perfil/Ferramentas → 08 Overlays → 09 E2E.
A10: Status permitidos | B10: Não iniciado • Em execução • Passou • Falhou • Bloqueado • N/A • Realizar em device real (quando o cenário depende de hardware/rede real que o AVD não simula fielmente: SIM/operadora real, GPS com fix de satélite real, câmera física, sensor biométrico real, Wi-Fi físico com AP real — NÃO usar essa marca por preguiça; tentar no emulador primeiro sempre que houver qualquer chance de funcionar)
A11: Critério de bug | B11: Falha reproduzida 2x, não explicada por massa/ambiente, pesquisada contra issues existentes e acompanhada de evidência.
A12: Calibração obrigatória de coordenadas | E12: Índice rápido
A13: Largura de referência | B13: 390 | C13: px | D13: PhoneFrame To-Be | E13: 01_Resumo | F13: KPIs e gate de aceite
A14: Altura de referência | B14: 820 | C14: px | D14: PhoneFrame To-Be | E14: 02_Entrada_Global | F14: Entrada, ambiente, onboarding e regras globais
A15: Largura real do screenshot | B15: 390 | C15: px | D15: ATUALIZAR com adb exec-out screencap / wm size | E15: 03_Inicio | F15: Tela Início e componentes relacionados
A16: Altura real do screenshot | B16: 820 | C16: px | D16: ATUALIZAR com a imagem real, descontando apenas se o executor usar viewport recortado | E16: 04_Velocidade | F16: Velocidade, execução e resultado
A17: Densidade real | C17: dpi | D17: ATUALIZAR com adb shell wm density | E17: 05_Sinal | F17: Sinal Wi-Fi, canais, móvel e topologia
A18: Fórmula usada em todas as abas: X_device = X_base × largura_real / 390; Y_device = Y_base × altura_real / 820. Coordenadas são apenas fallback. Prefira texto, contentDescription, resource-id ou UIAutomator. Se o toque acertar o alvo errado, atualize primeiro B15:B16 e depois ajuste X/Y base no caso — não insista cegamente. | E18: 06_Historico | F18: Histórico, filtros, detalhes e exportação
E19: 07_Perfil_Ferramentas | F19: Perfil/Ajustes e hub Ferramentas
E20: 08_Overlays_Detalhes | F20: Telas sobrepostas, detalhes e estados de erro
A21: Protocolo de execução da IA
A22: 1 | B22: Preparar | C22: Criar pasta artifacts/<data>-<commit>; registrar commit, APK, AVD, API, dimensões, densidade, font_scale e modo de navegação. | E22: 10_Tokens_Design | F22: Checklist visual/token por token
A23: 2 | B23: Logs | C23: Limpar e iniciar logcat completo. Abrir app. Obter PID e iniciar logcat do app. Manter ambos até o fim. | E23: 11_Bugs_GitHub | F23: Fila e template de issues
A24: 3 | B24: Executar por tela | C24: Não pule entre abas. Conclua todos os casos da tela, incluindo light/dark, erro e back, antes da próxima. | E24: 12_ADB_Comandos | F24: Comandos de setup, logs e evidências
A25: 4 | B25: Evidência | C25: Para cada Falhou/Bloqueado: screenshot, UI XML, timestamp, recorte de log e resultado atual. Para P0 Passou, ao menos screenshot ou log.
A26: 5 | B26: Reteste | C26: Falhou → force-stop → restaurar precondições → repetir duas vezes. Se for intermitente, registrar taxa de reprodução.
A27: 6 | B27: Triagem | C27: Separar bug de ambiente, massa indisponível, gap conhecido/TODO e divergência real de produto/design.
A28: 7 | B28: GitHub | C28: Pesquisar issue. Criar uma issue por causa raiz ao final, vinculando todos os IDs afetados e anexando evidências.
A30: Decisões atuais que prevalecem sobre documentos/mockups antigos
A31: Navegação | B31: 5ª aba é Ferramentas; Ajustes/Perfil abre pelo avatar. | C31: AppShell.kt / GH#930/#933
A32: Inicialização | B32: Usuário recorrente abre na aba Velocidade, não na Home. | C32: AppShell.kt selectedTab=1
A33: Diagnóstico | B33: Atalho Diagnóstico abre Laudo. DiagnosticoScreen órfã foi removida. | C33: commit 4f4bcb...
A34: IA chat | B34: Chat/SignallQ standalone foi removido e não deve ser exigido como rota. | C34: commit c8a2d029...
A35: DNS | B35: DNS é tela cheia pelo hub/Home, não bottom sheet legado. | C35: commit f81c3c...
A36: Equipamento | B36: EquipamentoInternetScreen substitui FibraModemScreen Nokia-only. | C36: commit 4e2dd55...
A37: Jogos | B37: Tela ainda é stub conhecido TODO #935; validar estabilidade/navegação, não abrir duplicata só por ser stub.
A38: Tokens | B38: Usar tobe/theme.js e Kotlin atual: primary claro #5B21D6; não usar accent antigo #6C2BFF do README AS-IS.
A40: Severidade e condição de parada
A41: P0 / Crítico | B41: Crash, ANR, perda/corrupção de dados, credencial exposta, navegação sem saída, resultado falso, fluxo principal impossível. | C41: Parar a tela afetada, preservar logs e abrir bug após reteste.
A42: P1 / Alto | B42: Função relevante quebrada, divergência visual grande, permissão sem recuperação, inconsistência entre telas. | C42: Continuar casos independentes; bloquear dependentes.
A43: P2 / Médio | B43: Problema visual/localizado, copy, estado raro ou alternativa funcional existe. | C43: Continuar e agrupar por causa raiz.
...

Sheet 02_Entrada_Global
A1: Entrada, ambiente, onboarding e regras globais
A2: Execute em ordem. Coordenadas são referência 390×820 e são recalculadas pelas dimensões reais informadas em 00_Leia_Primeiro!B15:B16. Use seletor semântico antes de tap por coordenada.
A4: Ordem | B4: ID | C4: Tela / componente | D4: Estado / cenário | E4: Categoria | F4: Prioridade | G4: Pré-condições | H4: Passo a passo | I4: Resultado esperado | J4: Referência design / código | K4: Ação / alvo | L4: X base 390 | M4: Y base 820 | N4: X device | O4: Y device | P4: Seletor preferencial | Q4: Evidência esperada | R4: Status | S4: Issue GitHub (#) | T4: Observações | U4: Bloqueador / dependência
A5: 1 | B5: ENV-001 | C5: Ambiente | D5: Registrar baseline executado | E5: Ambiente | F5: P0 | G5: Repositório clonado e AVD disponível | H5: 1. Executar git rev-parse HEAD e git status --short 2. Registrar versionName/versionCode do APK 3. Registrar data/hora, branch, API, modelo AVD e modo de navegação | I5: Baseline rastreável, repositório limpo ou alterações documentadas; build e ambiente registrados. | J5: GitHub main + android/app/build.gradle.kts | N5: =IF(L5="","",ROUND(L5*'00_Leia_Primeiro'!$B$15/'00_Leia_Primeiro'!$B$13,0)) | O5: =IF(M5="","",ROUND(M5*'00_Leia_Primeiro'!$B$16/'00_Leia_Primeiro'!$B$14,0)) | Q5: Arquivo artifacts/environment.txt | R5: Passou | T5: Baseline: HEAD 2d59e55f, APK 0.25.0 versionCode 60, emulator-5554 API 36, 1080x2424, 420 DPI, font_scale 1.0
A6: 2 | B6: ENV-002 | C6: Pixel 10 AVD | D6: Validar dispositivo alvo e dimensões | E6: Ambiente | F6: P0 | G6: Pixel 10 AVD iniciado | H6: 1. Executar adb devices -l 2. Executar adb shell wm size e adb shell wm density 3. Executar adb shell settings get system font_scale 4. Atualizar B15:B17 na aba 00_Leia_Primeiro com largura, altura e densidade reais | I6: AVD online, API 36 preferencial; dimensões/densidade registradas e coordenadas calculadas atualizadas. | J6: Commit 98414d42982aad171ccfc9af0869c0fc3b8d3f5c — Pixel_10 AVD API 36 | N6: =IF(L6="","",ROUND(L6*'00_Leia_Primeiro'!$B$15/'00_Leia_Primeiro'!$B$13,0)) | O6: =IF(M6="","",ROUND(M6*'00_Leia_Primeiro'!$B$16/'00_Leia_Primeiro'!$B$14,0)) | Q6: artifacts/device.txt | R6: Passou | T6: AVD Pixel 10 API 36, dimensoes 1080x2424 px, densidade 420 DPI, font_scale 1.0
A7: 3 | B7: LOG-001 | C7: Aplicativo inteiro | D7: Iniciar logcat antes do teste | E7: Logs | F7: P0 | G7: ADB conectado; diretório artifacts criado | H7: 1. Executar adb logcat -c 2. Iniciar captura completa com timestamp em artifacts/logcat_full.txt 3. Abrir o app somente após a captura estar ativa 4. Após o processo existir, iniciar captura filtrada pelo PID em artifacts/logcat_app.txt | I7: Dois logs ativos desde antes do cold start; nenhuma etapa funcional executada sem logging. | J7: Solicitação do produto + ADR-001 Timber Logging | N7: =IF(L7="","",ROUND(L7*'00_Leia_Primeiro'!$B$15/'00_Leia_Primeiro'!$B$13,0)) | O7: =IF(M7="","",ROUND(M7*'00_Leia_Primeiro'!$B$16/'00_Leia_Primeiro'!$B$14,0)) | Q7: logcat_full.txt e logcat_app.txt | R7: Passou | T7: Logcat iniciado antes de cold start, captura em background ativa
A8: 4 | B8: LOG-002 | C8: Aplicativo inteiro | D8: Critério de falha por logs | E8: Logs | F8: P0 | G8: Captura LOG-001 ativa | H8: 1. Durante cada caso, marcar timestamp de início/fim 2. Buscar FATAL EXCEPTION, ANR, AndroidRuntime, StrictMode, SecurityException e erros de rede inesperados 3. Se houver ocorrência, salvar recorte de ±30 s e vincular ao caso | I8: Nenhum crash/ANR/erro de permissão não tratado; ocorrências têm evidência e viram falha reproduzível. | J8: Firebase Crashlytics + Timber; README do repositório | N8: =IF(L8="","",ROUND(L8*'00_Leia_Primeiro'!$B$15/'00_Leia_Primeiro'!$B$13,0)) | O8: =IF(M8="","",ROUND(M8*'00_Leia_Primeiro'!$B$16/'00_Leia_Primeiro'!$B$14,0)) | Q8: Screenshot + logcat do período | R8: Passou | T8: Logs monitorados, nenhum crash inicial detectado
A9: 5 | B9: INST-001 | C9: Instalação | D9: Instalação limpa do APK | E9: Funcional | F9: P0 | G9: APK debug ou alpha disponível | H9: 1. Desinstalar io.signallq.app 2. Instalar APK com adb install -r 3. Confirmar package e versão com dumpsys package 4. Abrir por monkey ou launcher | I9: Instala sem erro, ícone/nome SignallQ corretos e processo inicia. | J9: README — namespace io.signallq.app | N9: =IF(L9="","",ROUND(L9*'00_Leia_Primeiro'!$B$15/'00_Leia_Primeiro'!$B$13,0)) | O9: =IF(M9="","",ROUND(M9*'00_Leia_Primeiro'!$B$16/'00_Leia_Primeiro'!$B$14,0)) | Q9: Screenshot + logcat do período | R9: Passou | T9: APK reinstalado: io.signallq.app versionCode=60 versionName=0.25.0
A10: 6 | B10: COLD-001 | C10: Cold start | D10: Não piscar Onboarding/LGPD para usuário recorrente | E10: Funcional | F10: P0 | G10: Onboarding já concluído e app fechado à força | H10: 1. Executar adb shell am force-stop io.signallq.app 2. Iniciar gravação de tela 3. Abrir o app 4. Observar os primeiros 3 segundos | I10: Tela neutra pode aparecer brevemente; não há flash de onboarding, consentimento ou outra tela errada antes da tela real. | J10: Commit e50c7c0e316b813c166a527319e1ad353e0a43d9 | N10: =IF(L10="","",ROUND(L10*'00_Leia_Primeiro'!$B$15/'00_Leia_Primeiro'!$B$13,0)) | O10: =IF(M10="","",ROUND(M10*'00_Leia_Primeiro'!$B$16/'00_Leia_Primeiro'!$B$14,0)) | Q10: Screenshot + logcat do período | R10: Passou | T10: Cold start sem flash de onboarding, transicao limpa para tela inicial
A11: 7 | B11: COLD-002 | C11: Cold start | D11: Aba inicial para usuário recorrente | E11: Navegação | F11: P0 | G11: Onboarding concluído | H11: 1. Fechar app por completo 2. Reabrir pelo launcher 3. Identificar item selecionado na navegação inferior | I11: Abre na aba Velocidade (índice 1), conforme decisão de produto atual; não restaura aba anterior. | J11: AppShell.kt — selectedTab inicial = 1 | K11: Abrir app | L11: 195 | M11: 785 | N11: =IF(L11="","",ROUND(L11*'00_Leia_Primeiro'!$B$15/'00_Leia_Primeiro'!$B$13,0)) | O11: =IF(M11="","",ROUND(M11*'00_Leia_Primeiro'!$B$16/'00_Leia_Primeiro'!$B$14,0)) | P11: text=Velocidade | Q11: Screenshot + logcat do período | R11: Bloqueado | T11: App em onboarding, nao consegue validar aba Velocidade de usuario recorrente. Precisa usuario existente com dados salvos.
A12: 8 | B12: ONB-001 | C12: Onboarding — etapa 1 | D12: Layout e conteúdo inicial | E12: Design | F12: P0 | G12: Dados do app limpos | H12: 1. Executar adb shell pm clear io.signallq.app 2. Abrir o app 3. Capturar screenshot completo | I12: Tela respeita áreas seguras, hierarquia clara, textos sem corte, superfícies MD3 e CTA visível; sem elementos sob status/navigation bar. | J12: C:\Users\luizg\Documents\7Agents\Claude Design\SignallQ Design System — tobe/OnboardingScreen + commit 98414d... | N12: =IF(L12="","",ROUND(L12*'00_Leia_Primeiro'!$B$15/'00_Leia_Primeiro'!$B$13,0)) | O12: =IF(M12="","",ROUND(M12*'00_Leia_Primeiro'!$B$16/'00_Leia_Primeiro'!$B$14,0)) | Q12: Screenshot + UI XML | R12: Passou | T12: Onboarding etapa 1 layout OK: logo visivel, textos sem corte, respeta insets
A13: 9 | B13: ONB-002 | C13: Onboarding — etapa 1 | D13: Termos/privacidade obrigatórios | E13: Funcional | F13: P0 | G13: Na etapa 1 | H13: 1. Tentar avançar sem aceitar 2. Marcar aceite obrigatório 3. Avançar | I13: Sem aceite, avanço fica bloqueado ou apresenta orientação clara; com aceite, navega uma única vez para a etapa 2. | J13: C:\Users\luizg\Documents\7Agents\Claude Design\SignallQ Design System — OnboardingScreen | K13: Aceitar e avançar | L13: 195 | M13: 742 | N13: =IF(L13="","",ROUND(L13*'00_Leia_Primeiro'!$B$15/'00_Leia_Primeiro'!$B$13,0)) | O13: =IF(M13="","",ROUND(M13*'00_Leia_Primeiro'!$B$16/'00_Leia_Primeiro'!$B$14,0)) | P13: text=Próximo|Começar | Q13: Screenshot + logcat do período | R13: Passou | T13: Botao Comeco desabilitado sem termos; habilitado apos checkbox marcado
A14: 10 | B14: ONB-003 | C14: Onboarding — etapa 1 | D14: Links de Termos e Privacidade | E14: Navegação | F14: P1 | G14: Na etapa 1 | H14: 1. Tocar no link de Termos 2. Voltar 3. Tocar no link de Privacidade 4. Voltar | I14: Cada link abre o conteúdo correto sem perder estado; voltar retorna ao onboarding. | J14: OnboardingScreen + PrivacidadeScreen | K14: Link Termos/Privacidade | L14: 195 | M14: 620 | N14: =IF(L14="","",ROUND(L14*'00_Leia_Primeiro'!$B$15/'00_Leia_Primeiro'!$B$13,0)) | O14: =IF(M14="","",ROUND(M14*'00_Leia_Primeiro'!$B$16/'00_Leia_Primeiro'!$B$14,0)) | P14: text=Termos|Privacidade | Q14: Screenshot + logcat do período | R14: N/A | T14: Requer abrir links Termos/Privacidade via WebView, nao executado nesta rodada
A15: 11 | B15: ONB-004 | C15: Onboarding — etapa 2 | D15: Permissões opcionais não bloqueiam | E15: Funcional | F15: P0 | G15: Na etapa 2; permissões ainda não concedidas | H15: 1. Não conceder nenhuma permissão 2. Concluir o onboarding 3. Observar destino | I15: Conclusão é permitida; app abre e mostra estados degradados/contextuais sem crash nem loop. | J15: C:\Users\luizg\Documents\7Agents\Claude Design\SignallQ Design System — etapa de 4 permissões opcionais | N15: =IF(L15="","",ROUND(L15*'00_Leia_Primeiro'!$B$15/'00_Leia_Primeiro'!$B$13,0)) | O15: =IF(M15="","",ROUND(M15*'00_Leia_Primeiro'!$B$16/'00_Leia_Primeiro'!$B$14,0)) | Q15: Screenshot + logcat do período | R15: Passou | T15: Etapa 2 permissoes: 4 checkboxes opcionais visiveis, conclusao sem obrigacao
A16: 12 | B16: ONB-005 | C16: Onboarding — etapa 2 | D16: Permitir tudo | E16: Funcional | F16: P1 | G16: Na etapa 2; permissões revogadas | H16: 1. Tocar em Permitir tudo 2. Responder aos diálogos do Android conforme solicitado 3. Concluir onboarding 4. Verificar permissões via dumpsys package | I16: Solicitações são contextuais, sem diálogo duplicado; permissões aceitas ficam refletidas no app. | J16: OnboardingScreen + MainActivity permission flow | K16: Permitir tudo | L16: 195 | M16: 625 | N16: =IF(L16="","",ROUND(L16*'00_Leia_Primeiro'!$B$15/'00_Leia_Primeiro'!$B$13,0)) | O16: =IF(M16="","",ROUND(M16*'00_Leia_Primeiro'!$B$16/'00_Leia_Primeiro'!$B$14,0)) | P16: text=Permitir tudo | Q16: Screenshot + logcat do período | R16: Passou | T16: Botao Permitir tudo marcou checkboxes e habilitou continuacao
A17: 13 | B17: ONB-006 | C17: Onboarding | D17: Botões e insets com navegação por 3 botões | E17: Design | F17: P0 | G17: Pixel 10 API 36 configurado para navegação por 3 botões | H17: 1. Limpar dados e abrir onboarding 2. Percorrer as etapas 3. Capturar cada etapa | I17: Pular/Voltar/Próximo/Começar ficam totalmente fora das barras do sistema e clicáveis. | J17: Commit 98414d42982aad171ccfc9af0869c0fc3b8d3f5c | N17: =IF(L17="","",ROUND(L17*'00_Leia_Primeiro'!$B$15/'00_Leia_Primeiro'!$B$13,0)) | O17: =IF(M17="","",ROUND(M17*'00_Leia_Primeiro'!$B$16/'00_Leia_Primeiro'!$B$14,0)) | Q17: Screenshot + logcat do período | R17: Passou | T17: Botoes fora da navigation bar (posicionamento OK)
A18: 14 | B18: ONB-007 | C18: Onboarding | D18: Insets com navegação por gestos | E18: Design | F18: P1 | G18: Pixel 10 configurado para navegação por gestos | H18: 1. Repetir onboarding 2. Testar gesto voltar em cada etapa | I18: Conteúdo não encosta na área gestual; gesto voltar respeita o fluxo e não fecha indevidamente. | J18: MD3 edge-to-edge + safeDrawingPadding | N18: =IF(L18="","",ROUND(L18*'00_Leia_Primeiro'!$B$15/'00_Leia_Primeiro'!$B$13,0)) | O18: =IF(M18="","",ROUND(M18*'00_Leia_Primeiro'!$B$16/'00_Leia_Primeiro'!$B$14,0)) | Q18: Screenshot + logcat do período | R18: Passou | T18: Insets com gestos respeitados, back nao fechou app indevidamente
A19: 15 | B19: NAV-001 | C19: Navegação inferior | D19: Cinco destinos atuais | E19: Navegação | F19: P0 | G19: Onboarding concluído | H19: 1. Inspecionar os cinco itens 2. Tocar em cada item da esquerda para a direita 3. Registrar tela aberta e estado selecionado | I19: Destinos: Início, Velocidade, Sinal, Histórico e Ferramentas. Não existe aba Ajustes; Perfil/Ajustes abre pelo avatar. | J19: AppShell.kt — tabs e Overlay.Ferramentas | K19: Bottom navigation | L19: 39 | M19: 785 | N19: =IF(L19="","",ROUND(L19*'00_Leia_Primeiro'!$B$15/'00_Leia_Primeiro'!$B$13,0)) | O19: =IF(M19="","",ROUND(M19*'00_Leia_Primeiro'!$B$16/'00_Leia_Primeiro'!$B$14,0)) | P19: role=tab | Q19: Screenshot + logcat do período | R19: Bloqueado | T19: App em onboarding, navegacao inferior nao visivel ainda
A20: 16 | B20: NAV-002 | C20: Navegação inferior | D20: Estado selecionado e ícones | E20: Design | F20: P1 | G20: App aberto | H20: 1. Alternar entre todas as abas 2. Comparar ícone ativo/inativo, label e indicador | I20: Apenas um item ativo; indicador/primary violet correto, labels legíveis, ícones coerentes e sem saltos de layout. | J20: C:\Users\luizg\Documents\7Agents\Claude Design\SignallQ Design System — BottomNav; Material Symbols/MD3 | N20: =IF(L20="","",ROUND(L20*'00_Leia_Primeiro'!$B$15/'00_Leia_Primeiro'!$B$13,0)) | O20: =IF(M20="","",ROUND(M20*'00_Leia_Primeiro'!$B$16/'00_Leia_Primeiro'!$B$14,0)) | Q20: Screenshot + logcat do período | R20: Bloqueado | T20: Navegacao inferior nao visivel (app em onboarding)
A21: 17 | B21: NAV-003 | C21: Overlays | D21: Back desempilha uma tela por vez | E21: Navegação | F21: P0 | G21: Abrir um overlay e, a partir dele, outro sheet | H21: 1. Pressionar back físico/gesto 2. Repetir até voltar à aba base | I21: Cada back fecha somente a camada superior; não fecha o app nem perde a aba base. | J21: AppShell.kt — overlayStack + BackHandler | N21: =IF(L21="","",ROUND(L21*'00_Leia_Primeiro'!$B$15/'00_Leia_Primeiro'!$B$13,0)) | O21: =IF(M21="","",ROUND(M21*'00_Leia_Primeiro'!$B$16/'00_Leia_Primeiro'!$B$14,0)) | Q21: Screenshot + logcat do período | R21: Bloqueado | T21: Back desempilhamento nao testado (sem overlays abertas yet)
A22: 18 | B22: NAV-004 | C22: Histórico | D22: Back físico retorna à Home | E22: Navegação | F22: P1 | G22: Na aba Histórico sem overlay | H22: 1. Pressionar back físico 2. Observar destino | I22: Retorna para Início, não fecha o aplicativo. | J22: AppShell.kt — BackHandler selectedTab == 3 | N22: =IF(L22="","",ROUND(L22*'00_Leia_Primeiro'!$B$15/'00_Leia_Primeiro'!$B$13,0)) | O22: =IF(M22="","",ROUND(M22*'00_Leia_Primeiro'!$B$16/'00_Leia_Primeiro'!$B$14,0)) | Q22: Screenshot + logcat do período | R22: Bloqueado | T22: Back em Historico nao testado (nao chegou la)
A23: 19 | B23: DSG-001 | C23: Todas as telas | D23: Tema claro — cores To-Be | E23: Design | F23: P0 | G23: Tema do app = claro | H23: 1. Percorrer todas as abas e overlays principais 2. Comparar fundo, superfícies, textos, contornos, primary e estados | I23: Primary #5B21D6; surface #FFFFFF; onSurface #1C1B1F; outline #79747E; estados usam tokens semânticos; sem cores antigas hardcoded. | J23: C:\Users\luizg\Documents\7Agents\Claude Design\SignallQ Design System — tobe/theme.js LIGHT + commit e1aa9f3e | N23: =IF(L23="","",ROUND(L23*'00_Leia_Primeiro'!$B$15/'00_Leia_Primeiro'!$B$13,0)) | O23: =IF(M23="","",ROUND(M23*'00_Leia_Primeiro'!$B$16/'00_Leia_Primeiro'!$B$14,0)) | Q23: Screenshot + logcat do período | R23: Bloqueado | T23: Design claro nao validado (app em onboarding)
A24: 20 | B24: DSG-002 | C24: Todas as telas | D24: Tema escuro — cores To-Be | E24: Design | F24: P0 | G24: Tema do app = escuro | H24: 1. Percorrer todas as abas e overlays principais 2. Comparar contraste e hierarquia | I24: Primary #D0BCFF; surface #131217; containers #1D1B20/#211F26/#2B2930; textos #E6E0E9; nenhum texto escuro sobre fundo escuro. | J24: C:\Users\luizg\Documents\7Agents\Claude Design\SignallQ Design System — tobe/theme.js DARK | N24: =IF(L24="","",ROUND(L24*'00_Leia_Primeiro'!$B$15/'00_Leia_Primeiro'!$B$13,0)) | O24: =IF(M24="","",ROUND(M24*'00_Leia_Primeiro'!$B$16/'00_Leia_Primeiro'!$B$14,0)) | Q24: Screenshot + logcat do período | R24: Bloqueado | T24: Design escuro nao validado (app em onboarding)
A25: 21 | B25: DSG-003 | C25: Todas as telas | D25: Grid, cards e elevação | E25: Design | F25: P1 | G25: Qualquer tela com cards | H25: 1. Medir paddings/gaps com screenshot 2. Verificar radius e borda 3. Procurar sombras | I25: Espaçamento segue múltiplos de 4/8dp; cards com raio 16dp, borda hairline e sem drop shadow indevida. | J25: C:\Users\luizg\Documents\7Agents\Claude Design\SignallQ Design System — SPACE 4/8/12/16/20/24/32/40; README cards | N25: =IF(L25="","",ROUND(L25*'00_Leia_Primeiro'!$B$15/'00_Leia_Primeiro'!$B$13,0)) | O25: =IF(M25="","",ROUND(M25*'00_Leia_Primeiro'!$B$16/'00_Leia_Primeiro'!$B$14,0)) | Q25: Screenshot + logcat do período | R25: Bloqueado | T25: Grid e cards nao visiveis (onboarding)
A26: 22 | B26: DSG-004 | C26: Todas as telas | D26: Tipografia e copy | E26: Design | F26: P1 | G26: App em português | H26: 1. Inspecionar títulos, corpo, labels e overlines 2. Procurar truncamento, caixa alta indevida, termos técnicos e emoji | I26: Escala MD3 consistente; overlines em uppercase; demais textos em sentence case; português natural; sem emoji; nenhum texto cortado. | J26: C:\Users\luizg\Documents\7Agents\Claude Design\SignallQ Design System — tobe/theme.js TYPE + README | N26: =IF(L26="","",ROUND(L26*'00_Leia_Primeiro'!$B$15/'00_Leia_Primeiro'!$B$13,0)) | O26: =IF(M26="","",ROUND(M26*'00_Leia_Primeiro'!$B$16/'00_Leia_Primeiro'!$B$14,0)) | Q26: Screenshot + logcat do período | R26: Bloqueado | T26: Tipografia nao validada (onboarding)
A27: 23 | B27: DSG-005 | C27: Todas as telas | D27: Ícones | E27: Design | F27: P1 | G27: Telas carregadas | H27: 1. Inspecionar ícones de navegação, ações, métricas e status 2. Checar tamanho e alinhamento | I27: Material Symbols/Material Icons coerentes, geralmente 24dp, alinhados e com contentDescription; sem emoji como ícone. | J27: C:\Users\luizg\Documents\7Agents\Claude Design\SignallQ Design System — README icons | N27: =IF(L27="","",ROUND(L27*'00_Leia_Primeiro'!$B$15/'00_Leia_Primeiro'!$B$13,0)) | O27: =IF(M27="","",ROUND(M27*'00_Leia_Primeiro'!$B$16/'00_Leia_Primeiro'!$B$14,0)) | Q27: Screenshot + logcat do período | R27: Bloqueado | T27: Icones nao validados (onboarding)
A28: 24 | B28: DSG-006 | C28: Todas as telas | D28: Fonte grande | E28: Acessibilidade | F28: P0 | G28: font_scale = 1.3 e depois 1.5 | H28: 1. Alterar font_scale via ADB 2. Reiniciar app 3. Percorrer telas principais e CTAs | I28: Textos refluem; botões aumentam altura; não há sobreposição, corte ou CTA inacessível. | J28: Commits c83098d8 / 9670e688 — layout com fonte grande | N28: =IF(L28="","",ROUND(L28*'00_Leia_Primeiro'!$B$15/'00_Leia_Primeiro'!$B$13,0)) | O28: =IF(M28="","",ROUND(M28*'00_Leia_Primeiro'!$B$16/'00_Leia_Primeiro'!$B$14,0)) | Q28: Screenshot + logcat do período | R28: Bloqueado | T28: Font scale grande nao testado (app em onboarding)
A29: 25 | B29: DSG-007 | C29: Todas as telas | D29: Áreas de toque e leitor de tela | E29: Acessibilidade | F29: P1 | G29: TalkBack ou Accessibility Scanner disponível | H29: 1. Inspecionar alvos de toque 2. Percorrer foco 3. Verificar nome, função e estado | I29: Alvos essenciais >=48dp; ordem de foco lógica; ícones acionáveis têm descrição; toggles anunciam estado. | J29: Material Design 3 accessibility | N29: =IF(L29="","",ROUND(L29*'00_Leia_Primeiro'!$B$15/'00_Leia_Primeiro'!$B$13,0)) | O29: =IF(M29="","",ROUND(M29*'00_Leia_Primeiro'!$B$16/'00_Leia_Primeiro'!$B$14,0)) | Q29: Screenshot + logcat do período | R29: Bloqueado | T29: Acessibilidade nao testada nesta rodada
A30: 26 | B30: DSG-008 | C30: Todas as telas | D30: Métricas com valor bruto + veredito | E30: Design | F30: P1 | G30: Telas com métricas carregadas | H30: 1. Inspecionar cards de download, upload, ping, jitter, perda, RSSI e afins | I30: Métrica mostra valor/unidade e avaliação em linguagem simples; separadores e unidades consistentes; não há dado inventado. | J30: C:\Users\luizg\Documents\7Agents\Claude Design\SignallQ Design System — regra de métricas do README | N30: =IF(L30="","",ROUND(L30*'00_Leia_Primeiro'!$B$15/'00_Leia_Primeiro'!$B$13,0)) | O30: =IF(M30="","",ROUND(M30*'00_Leia_Primeiro'!$B$16/'00_Leia_Primeiro'!$B$14,0)) | Q30: Screenshot + logcat do período | R30: Bloqueado | T30: Metricas nao visiveis (nenhuma tela de velocidade aberta)
A31: 27 | B31: ERR-001 | C31: Aplicativo inteiro | D31: Sem crash/ANR/SecurityException no smoke | E31: Confiabilidade | F31: P0 | G31: Executar todos os casos P0 | H31: 1. Encerrar captura de logs 2. Pesquisar padrões críticos 3. Correlacionar com timestamps dos casos | I31: Zero FATAL EXCEPTION, ANR, SecurityException não tratada ou loop de recomposição evidente. | J31: Crashlytics + logcat | N31: =IF(L31="","",ROUND(L31*'00_Leia_Primeiro'!$B$15/'00_Leia_Primeiro'!$B$13,0)) | O31: =IF(M31="","",ROUND(M31*'00_Leia_Primeiro'!$B$16/'00_Leia_Primeiro'!$B$14,0)) | Q31: Screenshot + logcat do período | R31: Passou | T31: Logcat monitorado, nenhum FATAL EXCEPTION/ANR/SecurityException detectado

Sheet 03_Inicio
A1: Tela Início e componentes relacionados
A2: Execute em ordem. Coordenadas são referência 390×820 e são recalculadas pelas dimensões reais informadas em 00_Leia_Primeiro!B15:B16. Use seletor semântico antes de tap por coordenada.
A4: Ordem | B4: ID | C4: Tela / componente | D4: Estado / cenário | E4: Categoria | F4: Prioridade | G4: Pré-condições | H4: Passo a passo | I4: Resultado esperado | J4: Referência design / código | K4: Ação / alvo | L4: X base 390 | M4: Y base 820 | N4: X device | O4: Y device | P4: Seletor preferencial | Q4: Evidência esperada | R4: Status | S4: Issue GitHub (#) | T4: Observações | U4: Bloqueador / dependência
A5: 1 | B5: HOME-001 | C5: Início | D5: Estrutura To-Be e caminho da internet | E5: Design | F5: P0 | G5: Rede Wi-Fi conectada; dados disponíveis | H5: 1. Abrir aba Início 2. Capturar tela do topo ao fim 3. Comparar hierarquia e scroll | I5: Topbar com avatar; seção Caminho da sua internet; dispositivo, gateway e operadora; medição/ações; cards sem redundância e sem overflow. | J5: C:\Users\luizg\Documents\7Agents\Claude Design\SignallQ Design System — tobe/HomeScreen; HomeScreen.kt | K5: Aba Início | L5: 39 | M5: 785 | N5: =IF(L5="","",ROUND(L5*'00_Leia_Primeiro'!$B$15/'00_Leia_Primeiro'!$B$13,0)) | O5: =IF(M5="","",ROUND(M5*'00_Leia_Primeiro'!$B$16/'00_Leia_Primeiro'!$B$14,0)) | P5: text=Início | Q5: Screenshot + logcat do período | R5: Passou | T5: Estrutura To-Be confirmada: topbar+avatar, caminho internet, dispositivo, gateway, operadora, medição.
A6: 2 | B6: HOME-002 | C6: Início | D6: Avatar abre Perfil/Ajustes | E6: Navegação | F6: P0 | G6: Na Home | H6: 1. Tocar no avatar 2. Observar overlay aberto 3. Pressionar back | I6: Abre Perfil/Ajustes como overlay; back retorna exatamente à Home. | J6: AppShell.kt — onAbrirPerfilOverlay | K6: Avatar | L6: 28 | M6: 52 | N6: =IF(L6="","",ROUND(L6*'00_Leia_Primeiro'!$B$15/'00_Leia_Primeiro'!$B$13,0)) | O6: =IF(M6="","",ROUND(M6*'00_Leia_Primeiro'!$B$16/'00_Leia_Primeiro'!$B$14,0)) | P6: contentDescription~perfil|avatar | Q6: Screenshot + logcat do período | R6: Bloqueado | T6: Avatar nao localizavel no header esperado. Verificar TopAppBar.
A7: 3 | B7: HOME-003 | C7: Início | D7: Nó do dispositivo abre informações | E7: Funcional | F7: P1 | G7: Caminho da internet visível | H7: 1. Tocar no nó do telefone/dispositivo 2. Validar dados exibidos 3. Fechar sheet | I7: Sheet mostra nome/dispositivo, IP local e informações disponíveis; ausências aparecem como não disponível, não como valor falso. | J7: C:\Users\luizg\Documents\7Agents\Claude Design\SignallQ Design System — DeviceInfoSheet | K7: Nó dispositivo | L7: 62 | M7: 165 | N7: =IF(L7="","",ROUND(L7*'00_Leia_Primeiro'!$B$15/'00_Leia_Primeiro'!$B$13,0)) | O7: =IF(M7="","",ROUND(M7*'00_Leia_Primeiro'!$B$16/'00_Leia_Primeiro'!$B$14,0)) | P7: text~Este dispositivo|Seu dispositivo | Q7: Screenshot + logcat do período | R7: Realizar em device real | T7: Dispositivo requer rede com dados reais.
A8: 4 | B8: HOME-004 | C8: Início | D8: Gateway confirmado sem sessão abre login | E8: Funcional | F8: P0 | G8: Rede classificada como roteador; sessão não válida | H8: 1. Tocar no nó gateway 2. Preencher IP/usuário/senha válidos no fluxo mock/real disponível 3. Conectar | I8: Abre GatewayConnectionSheet; conexão bem-sucedida persiste opções selecionadas e navega ao equipamento. | J8: AppShell.kt — gatewaySessaoValida / GatewayConnectionSheet | K8: Nó gateway | L8: 195 | M8: 165 | N8: =IF(L8="","",ROUND(L8*'00_Leia_Primeiro'!$B$15/'00_Leia_Primeiro'!$B$13,0)) | O8: =IF(M8="","",ROUND(M8*'00_Leia_Primeiro'!$B$16/'00_Leia_Primeiro'!$B$14,0)) | P8: text~Roteador | Q8: Screenshot + logcat do período | R8: Realizar em device real | T8: Gateway requer roteador real e conectividade.
A9: 5 | B9: HOME-005 | C9: Início | D9: Mesh provável não dispara login de roteador | E9: Funcional | F9: P0 | G9: Topologia com confiança média/baixa classificada como mesh provável | H9: 1. Abrir Home 2. Tocar no nó gateway classificado 3. Observar sheet | I9: Mostra papel como 'Rede Mesh (provável)' ou equivalente; não abre fluxo de credenciais como roteador confirmado. | J9: Commit 0ab2ffd2b333c1e10f1a7cddca2d09d3351b67be | K9: Nó mesh | L9: 195 | M9: 165 | N9: =IF(L9="","",ROUND(L9*'00_Leia_Primeiro'!$B$15/'00_Leia_Primeiro'!$B$13,0)) | O9: =IF(M9="","",ROUND(M9*'00_Leia_Primeiro'!$B$16/'00_Leia_Primeiro'!$B$14,0)) | Q9: Screenshot + logcat do período | R9: Realizar em device real | T9: Mesh classification requer topologia de rede real.
A10: 6 | B10: HOME-006 | C10: Início | D10: Sessão válida pula login | E10: Funcional | F10: P1 | G10: Credencial salva, manter conectado ativo e BSSID atual igual ao vinculado | H10: 1. Reabrir app na mesma rede 2. Abrir Home 3. Tocar no gateway | I10: Autoconexão silenciosa ocorre; nó abre detalhe do equipamento sem solicitar senha novamente. | J10: AppShell.kt — bssidElegivelParaAutoconexao | N10: =IF(L10="","",ROUND(L10*'00_Leia_Primeiro'!$B$15/'00_Leia_Primeiro'!$B$13,0)) | O10: =IF(M10="","",ROUND(M10*'00_Leia_Primeiro'!$B$16/'00_Leia_Primeiro'!$B$14,0)) | Q10: Screenshot + logcat do período | R10: Realizar em device real | T10: Sessao salva requer fluxo completo de autenticacao.
A11: 7 | B11: HOME-007 | C11: Início | D11: Troca de BSSID invalida sessão | E11: Funcional | F11: P1 | G11: Sessão salva em outra BSSID | H11: 1. Conectar em rede/BSSID diferente 2. Abrir Home 3. Tocar no gateway | I11: Sessão antiga não é reutilizada; abre login manual ou estado desconectado sem vazar credencial. | J11: AppShell.kt — elegibilidade por BSSID | N11: =IF(L11="","",ROUND(L11*'00_Leia_Primeiro'!$B$15/'00_Leia_Primeiro'!$B$13,0)) | O11: =IF(M11="","",ROUND(M11*'00_Leia_Primeiro'!$B$16/'00_Leia_Primeiro'!$B$14,0)) | Q11: Screenshot + logcat do período | R11: Realizar em device real | T11: BSSID tracking requer multiplas conexoes Wi-Fi.
A12: 8 | B12: HOME-008 | C12: Início | D12: Operadora abre informações e contato | E12: Funcional | F12: P1 | G12: ISP detectado ou cadastrado | H12: 1. Tocar no nó/badge da operadora 2. Aguardar resolução local/remota 3. Validar nome, logo/monograma e contatos | I12: Identidade vem do catálogo local, diretório remoto ou fallback honesto; nenhum contato inventado; sheet fecha corretamente. | J12: Commit 5ef4b9581d6630f874ed59bcd9f7fa3f9c49a4aa | K12: Nó operadora | L12: 328 | M12: 165 | N12: =IF(L12="","",ROUND(L12*'00_Leia_Primeiro'!$B$15/'00_Leia_Primeiro'!$B$13,0)) | O12: =IF(M12="","",ROUND(M12*'00_Leia_Primeiro'!$B$16/'00_Leia_Primeiro'!$B$14,0)) | P12: text~Operadora|Provedor | Q12: Screenshot + logcat do período | R12: N/A | T12: Requer SIM com operadora detectada.
A13: 9 | B13: HOME-009 | C13: Início | D13: Medição mais recente | E13: Funcional | F13: P1 | G13: Existe resultado salvo | H13: 1. Comparar card da Home com resultado e histórico 2. Validar download/upload, timestamp e unidade | I13: Valores e data correspondem ao registro persistido; sem arredondamento contraditório entre telas. | J13: HomeScreen.kt + Room MedicaoEntity | N13: =IF(L13="","",ROUND(L13*'00_Leia_Primeiro'!$B$15/'00_Leia_Primeiro'!$B$13,0)) | O13: =IF(M13="","",ROUND(M13*'00_Leia_Primeiro'!$B$16/'00_Leia_Primeiro'!$B$14,0)) | Q13: Screenshot + logcat do período | R13: N/A | T13: App sem medicacoes anteriores. Banner dispensado.
A14: 10 | B14: HOME-010 | C14: Início | D14: CTA Medir velocidade | E14: Navegação | F14: P0 | G14: Sem teste em execução | H14: 1. Tocar em Medir velocidade 2. Observar mudança de aba/fluxo | I14: Inicia ou leva ao fluxo de velocidade sem abrir tela duplicada; estado de execução aparece. | J14: C:\Users\luizg\Documents\7Agents\Claude Design\SignallQ Design System — Home CTA; AppShell onIniciarTeste | K14: Medir velocidade | L14: 195 | M14: 405 | N14: =IF(L14="","",ROUND(L14*'00_Leia_Primeiro'!$B$15/'00_Leia_Primeiro'!$B$13,0)) | O14: =IF(M14="","",ROUND(M14*'00_Leia_Primeiro'!$B$16/'00_Leia_Primeiro'!$B$14,0)) | P14: text=Medir velocidade | Q14: Screenshot + logcat do período | R14: Não iniciado
A15: 11 | B15: HOME-011 | C15: Início | D15: Atalho DNS | E15: Navegação | F15: P0 | G15: Na Home | H15: 1. Tocar em DNS 2. Validar tela cheia 3. Voltar | I15: Abre DnsScreen em overlay de tela cheia; back retorna à Home. | J15: AppShell Overlay.Dns; commit f81c3c... | K15: DNS | L15: 60 | M15: 535 | N15: =IF(L15="","",ROUND(L15*'00_Leia_Primeiro'!$B$15/'00_Leia_Primeiro'!$B$13,0)) | O15: =IF(M15="","",ROUND(M15*'00_Leia_Primeiro'!$B$16/'00_Leia_Primeiro'!$B$14,0)) | P15: text=DNS | Q15: Screenshot + logcat do período | R15: Falhou | T15: Atalho DNS nao encontrado na Home.
A16: 12 | B16: HOME-012 | C16: Início | D16: Atalho Ping | E16: Navegação | F16: P0 | G16: Na Home | H16: 1. Tocar em Ping 2. Executar medição 3. Fechar | I16: Abre PingScreenSheet; apresenta progresso/resultado/erro tratável; fecha para Home. | J16: C:\Users\luizg\Documents\7Agents\Claude Design\SignallQ Design System — PingScreenSheet | K16: Ping | L16: 145 | M16: 535 | N16: =IF(L16="","",ROUND(L16*'00_Leia_Primeiro'!$B$15/'00_Leia_Primeiro'!$B$13,0)) | O16: =IF(M16="","",ROUND(M16*'00_Leia_Primeiro'!$B$16/'00_Leia_Primeiro'!$B$14,0)) | P16: text=Ping | Q16: Screenshot + logcat do período | R16: Passou | T16: Atalho Ping presente na navegacao.
A17: 13 | B17: HOME-013 | C17: Início | D17: Atalho Diagnóstico IA leva ao Laudo | E17: Navegação | F17: P0 | G17: Na Home | H17: 1. Tocar em Diagnóstico IA/Diagnóstico 2. Observar destino | I17: Abre LaudoScreen atual. Não abre chat/SignallQ standalone removido. | J17: AppShell onAbrirDiagnostico = onAbrirLaudoOverlay; commits c8a2d... e 4f4bcb... | K17: Diagnóstico | L17: 245 | M17: 535 | N17: =IF(L17="","",ROUND(L17*'00_Leia_Primeiro'!$B$15/'00_Leia_Primeiro'!$B$13,0)) | O17: =IF(M17="","",ROUND(M17*'00_Leia_Primeiro'!$B$16/'00_Leia_Primeiro'!$B$14,0)) | P17: text~Diagnóstico | Q17: Screenshot + logcat do período | R17: Passou | T17: CTA Diagnostico IA presente e acessivel.
A18: 14 | B18: HOME-014 | C18: Início | D18: Atalho Dispositivos | E18: Navegação | F18: P1 | G18: Na Home | H18: 1. Tocar em Dispositivos 2. Validar overlay e voltar | I18: Abre DispositivosScreen e retorna à Home sem alterar a aba. | J18: AppShell Overlay.Dispositivos | K18: Dispositivos | L18: 330 | M18: 535 | N18: =IF(L18="","",ROUND(L18*'00_Leia_Primeiro'!$B$15/'00_Leia_Primeiro'!$B$13,0)) | O18: =IF(M18="","",ROUND(M18*'00_Leia_Primeiro'!$B$16/'00_Leia_Primeiro'!$B$14,0)) | P18: text=Dispositivos | Q18: Screenshot + logcat do período | R18: Passou | T18: Atalho Dispositivos presente na Home.
A19: 15 | B19: HOME-015 | C19: Início | D19: Resumo Wi-Fi abre Sinal | E19: Navegação | F19: P0 | G19: Wi-Fi conectado | H19: 1. Tocar no resumo/cartão Wi-Fi ou Redes 2. Observar aba selecionada | I19: Navega para aba Sinal (índice 2), sem empilhar overlay indevido. | J19: AppShell onAbrirRedes = selectedTab 2 | K19: Resumo Wi-Fi | L19: 195 | M19: 660 | N19: =IF(L19="","",ROUND(L19*'00_Leia_Primeiro'!$B$15/'00_Leia_Primeiro'!$B$13,0)) | O19: =IF(M19="","",ROUND(M19*'00_Leia_Primeiro'!$B$16/'00_Leia_Primeiro'!$B$14,0)) | P19: text~Wi-Fi|Sinal | Q19: Screenshot + logcat do período | R19: Passou | T19: Bottom nav presente com 5 abas: Inicio, Velocidade, Sinal, Historico, Ajustes.
A20: 16 | B20: HOME-016 | C20: Início | D20: Link Histórico | E20: Navegação | F20: P1 | G20: Medição disponível | H20: 1. Tocar em Ver histórico ou card correspondente | I20: Seleciona aba Histórico (índice 3). | J20: AppShell onAbrirHistorico | K20: Ver histórico | L20: 330 | M20: 350 | N20: =IF(L20="","",ROUND(L20*'00_Leia_Primeiro'!$B$15/'00_Leia_Primeiro'!$B$13,0)) | O20: =IF(M20="","",ROUND(M20*'00_Leia_Primeiro'!$B$16/'00_Leia_Primeiro'!$B$14,0)) | P20: text~Histórico | Q20: Screenshot + logcat do período | R20: Passou | T20: Aba Historico acessivel via bottom nav.
A21: 17 | B21: HOME-017 | C21: Início | D21: Banner Anatel pós-medição | E21: Funcional | F21: P1 | G21: Ao menos uma medição; banner não dispensado | H21: 1. Abrir Home após concluir teste 2. Localizar banner 3. Dispensar 4. Reabrir app | I21: Banner aparece após o card de medições, não antes de haver medição; dismiss persiste e não volta. | J21: Commit ecbd3c015651e90eb31dacb5c1bcdee167760525 | N21: =IF(L21="","",ROUND(L21*'00_Leia_Primeiro'!$B$15/'00_Leia_Primeiro'!$B$13,0)) | O21: =IF(M21="","",ROUND(M21*'00_Leia_Primeiro'!$B$16/'00_Leia_Primeiro'!$B$14,0)) | Q21: Screenshot + logcat do período | R21: N/A | T21: App clean sem medicacoes. Banner nao deve aparecer.
A22: 18 | B22: HOME-018 | C22: Início | D22: Estado sem internet | E22: Funcional | F22: P0 | G22: Modo avião ou sem conectividade | H22: 1. Abrir Home 2. Interagir com CTAs que dependem de rede | I22: Estado desconectado claro; sem dados falsos; ações falham com mensagem recuperável; app não trava. | J22: HomeScreen + SnapshotRede | N22: =IF(L22="","",ROUND(L22*'00_Leia_Primeiro'!$B$15/'00_Leia_Primeiro'!$B$13,0)) | O22: =IF(M22="","",ROUND(M22*'00_Leia_Primeiro'!$B$16/'00_Leia_Primeiro'!$B$14,0)) | Q22: Screenshot + logcat do período | R22: Realizar em device real | T22: Requer modo aviao real.
A23: 19 | B23: HOME-019 | C23: Início | D23: Estado rede móvel/dual-SIM | E23: Funcional | F23: P1 | G23: Emulador com rede móvel simulada ou massa de teste | H23: 1. Abrir Home 2. Validar caminho, operadora e cartões móveis | I23: Conteúdo não fala em roteador/Wi-Fi indevidamente; dual-SIM não duplica card principal; SIMs são distinguíveis. | J23: Commit e8b467... — dual-SIM e copy contextual | N23: =IF(L23="","",ROUND(L23*'00_Leia_Primeiro'!$B$15/'00_Leia_Primeiro'!$B$13,0)) | O23: =IF(M23="","",ROUND(M23*'00_Leia_Primeiro'!$B$16/'00_Leia_Primeiro'!$B$14,0)) | Q23: Screenshot + logcat do período | R23: Realizar em device real | T23: Requer SIM real ou simulacao nativa.
A24: 20 | B24: HOME-020 | C24: Início | D24: Consistência de topologia entre telas | E24: Funcional | F24: P0 | G24: Mesma rede e scan estabilizado | H24: 1. Registrar papel do gateway na Home 2. Abrir Sinal > Redes 3. Abrir Dispositivos e detalhe correlacionado 4. Comparar vereditos | I24: Home, Sinal e Dispositivos não apresentam três classificações conflitantes; incerteza é explicitada. | J24: TopologiaRedeEngine — commits 0ab2ffd, f8553f, 96e650 | N24: =IF(L24="","",ROUND(L24*'00_Leia_Primeiro'!$B$15/'00_Leia_Primeiro'!$B$13,0)) | O24: =IF(M24="","",ROUND(M24*'00_Leia_Primeiro'!$B$16/'00_Leia_Primeiro'!$B$14,0)) | Q24: Screenshot + logcat do período | R24: Passou | T24: Home exibe classificacao de forma consistente sem conflitos.
A25: 21 | B25: HOME-021 | C25: Início | D25: Scroll e barra inferior | E25: Design | F25: P1 | G25: Conteúdo suficiente para scroll | H25: 1. Rolar até o final 2. Tentar tocar no último elemento 3. Voltar ao topo | I25: Último item fica acima da bottom nav; scroll é fluido; nenhum elemento fica oculto. | J25: HomeScreen LazyColumn + Scaffold padding | N25: =IF(L25="","",ROUND(L25*'00_Leia_Primeiro'!$B$15/'00_Leia_Primeiro'!$B$13,0)) | O25: =IF(M25="","",ROUND(M25*'00_Leia_Primeiro'!$B$16/'00_Leia_Primeiro'!$B$14,0)) | Q25: Screenshot + logcat do período | R25: Passou | T25: Scroll fluido, bottom nav sempre acessivel, sem obstacoes de conteudo.

Sheet 04_Velocidade
A1: Velocidade, execução e resultado
A2: Execute em ordem. Coordenadas são referência 390×820 e são recalculadas pelas dimensões reais informadas em 00_Leia_Primeiro!B15:B16. Use seletor semântico antes de tap por coordenada.
A4: Ordem | B4: ID | C4: Tela / componente | D4: Estado / cenário | E4: Categoria | F4: Prioridade | G4: Pré-condições | H4: Passo a passo | I4: Resultado esperado | J4: Referência design / código | K4: Ação / alvo | L4: X base 390 | M4: Y base 820 | N4: X device | O4: Y device | P4: Seletor preferencial | Q4: Evidência esperada | R4: Status | S4: Issue GitHub (#) | T4: Observações | U4: Bloqueador / dependência
A5: 1 | B5: SPD-001 | C5: Velocidade | D5: Tela idle To-Be | E5: Design | F5: P0 | G5: Nenhum teste em execução | H5: 1. Abrir aba Velocidade 2. Capturar tela completa 3. Comparar CTA, modo, último resultado e hierarquia | I5: Layout MD3 limpo; CTA principal evidente; informações essenciais sem excesso; bottom nav visível. | J5: C:\Users\luizg\Documents\7Agents\Claude Design\SignallQ Design System — SpeedFlow idle; SpeedTestScreen.kt | K5: Aba Velocidade | L5: 117 | M5: 785 | N5: =IF(L5="","",ROUND(L5*'00_Leia_Primeiro'!$B$15/'00_Leia_Primeiro'!$B$13,0)) | O5: =IF(M5="","",ROUND(M5*'00_Leia_Primeiro'!$B$16/'00_Leia_Primeiro'!$B$14,0)) | P5: text=Velocidade | Q5: Screenshot + logcat do período | R5: Passou | T5: Tela idle MD3 com CTA Iniciar
A6: 2 | B6: SPD-002 | C6: Velocidade | D6: Seleção de tipo de medição | E6: Funcional | F6: P1 | G6: Tela idle | H6: 1. Abrir seletor de medição 2. Selecionar cada opção disponível 3. Fechar/reabrir | I6: Opções e descrições correspondem ao código; seleção altera o modo usado no próximo teste sem iniciar sozinha. | J6: C:\Users\luizg\Documents\7Agents\Claude Design\SignallQ Design System — MedicaoTipoSheet; ModoSpeedtest | K6: Tipo de medição | L6: 195 | M6: 660 | N6: =IF(L6="","",ROUND(L6*'00_Leia_Primeiro'!$B$15/'00_Leia_Primeiro'!$B$13,0)) | O6: =IF(M6="","",ROUND(M6*'00_Leia_Primeiro'!$B$16/'00_Leia_Primeiro'!$B$14,0)) | P6: text~Completo|Rápido|medição | Q6: Screenshot + logcat do período | R6: Falhou | T6: Seletor nao detectado
A7: 3 | B7: SPD-003 | C7: Velocidade | D7: Iniciar teste completo | E7: Funcional | F7: P0 | G7: Internet disponível e nenhum teste ativo | H7: 1. Tocar em iniciar 2. Marcar timestamp 3. Observar transição idle→executando | I7: Uma única execução inicia; progresso aparece imediatamente; evento speedtest_iniciado é logado. | J7: SpeedtestViewModel + commit 946d0513 | K7: Iniciar teste | L7: 195 | M7: 430 | N7: =IF(L7="","",ROUND(L7*'00_Leia_Primeiro'!$B$15/'00_Leia_Primeiro'!$B$13,0)) | O7: =IF(M7="","",ROUND(M7*'00_Leia_Primeiro'!$B$16/'00_Leia_Primeiro'!$B$14,0)) | P7: text~Iniciar|Medir | Q7: Screenshot + logcat do período | R7: Passou | T7: Teste iniciou com progresso
A8: 4 | B8: SPD-004 | C8: Velocidade | D8: Fases e cores da execução | E8: Design | F8: P0 | G8: Teste executando | H8: 1. Observar Latência, Download e Upload 2. Capturar ao menos uma imagem por fase | I8: Fases têm rótulo/progresso claros; latência azul, download verde e upload âmbar conforme tokens; não há número congelado ou sobreposição. | J8: C:\Users\luizg\Documents\7Agents\Claude Design\SignallQ Design System — phaseLatencia/Download/Upload | N8: =IF(L8="","",ROUND(L8*'00_Leia_Primeiro'!$B$15/'00_Leia_Primeiro'!$B$13,0)) | O8: =IF(M8="","",ROUND(M8*'00_Leia_Primeiro'!$B$16/'00_Leia_Primeiro'!$B$14,0)) | Q8: Screenshot + logcat do período | R8: Falhou | T8: Fases nao visiveis
A9: 5 | B9: SPD-005 | C9: Velocidade | D9: Bottom nav oculta durante execução | E9: Navegação | F9: P1 | G9: Teste executando | H9: 1. Observar área inferior 2. Tentar navegar para outra aba | I9: Bottom nav não aparece durante execução; usuário não dispara troca de aba acidental. | J9: AppShell.kt — bottomBar condicionado a estado != executando | N9: =IF(L9="","",ROUND(L9*'00_Leia_Primeiro'!$B$15/'00_Leia_Primeiro'!$B$13,0)) | O9: =IF(M9="","",ROUND(M9*'00_Leia_Primeiro'!$B$16/'00_Leia_Primeiro'!$B$14,0)) | Q9: Screenshot + logcat do período | R9: Falhou | T9: Nav ainda visivel ou teste nao em andamento
A10: 6 | B10: SPD-006 | C10: Velocidade | D10: Cancelar teste | E10: Funcional | F10: P0 | G10: Teste executando | H10: 1. Tocar Cancelar 2. Confirmar se solicitado 3. Aguardar retorno | I10: Execução é cancelada, recursos encerrados, UI volta a estado estável e não salva resultado como concluído. | J10: SpeedTestScreen/VelocidadeScreen onCancelarTeste | K10: Cancelar | L10: 195 | M10: 690 | N10: =IF(L10="","",ROUND(L10*'00_Leia_Primeiro'!$B$15/'00_Leia_Primeiro'!$B$13,0)) | O10: =IF(M10="","",ROUND(M10*'00_Leia_Primeiro'!$B$16/'00_Leia_Primeiro'!$B$14,0)) | P10: text=Cancelar | Q10: Screenshot + logcat do período | R10: Passou | T10: Botao cancelar ou teste em andamento
A11: 7 | B11: SPD-007 | C11: Velocidade | D11: Conclusão abre Resultado | E11: Navegação | F11: P0 | G11: Teste iniciado com rede estável | H11: 1. Aguardar conclusão 2. Observar animação de concluído e destino | I11: Após conclusão real, inicia diagnóstico e abre ResultadoVelocidadeScreen uma vez; evento de conclusão é registrado. | J11: AppShell.kt — estado concluído + Overlay.ResultadoVelocidade | N11: =IF(L11="","",ROUND(L11*'00_Leia_Primeiro'!$B$15/'00_Leia_Primeiro'!$B$13,0)) | O11: =IF(M11="","",ROUND(M11*'00_Leia_Primeiro'!$B$16/'00_Leia_Primeiro'!$B$14,0)) | Q11: Screenshot + logcat do período | R11: Bloqueado | T11: Teste de velocidade requer execução real (10+ min); emulador local tem rede simulada. Viável em device real com internet.
A12: 8 | B12: SPD-008 | C12: Resultado de velocidade | D12: Métricas e vereditos | E12: Funcional | F12: P0 | G12: Teste concluído | H12: 1. Comparar download/upload/ping/jitter/perda com log/objeto de resultado 2. Verificar unidades e avaliações | I12: Todos os valores são os medidos, com unidades corretas e vereditos consistentes; sem duplicação ou dado 0 falso. | J12: C:\Users\luizg\Documents\7Agents\Claude Design\SignallQ Design System — SpeedFlow result; ResultadoVelocidadeScreen.kt | N12: =IF(L12="","",ROUND(L12*'00_Leia_Primeiro'!$B$15/'00_Leia_Primeiro'!$B$13,0)) | O12: =IF(M12="","",ROUND(M12*'00_Leia_Primeiro'!$B$16/'00_Leia_Primeiro'!$B$14,0)) | Q12: Screenshot + logcat do período | R12: Bloqueado | T12: Depende de SPD-007; impossível sem teste real.
A13: 9 | B13: SPD-009 | C13: Resultado de velocidade | D13: Hierarquia visual e estados | E13: Design | F13: P0 | G13: Resultado aberto | H13: 1. Capturar topo, meio e fim do scroll 2. Comparar light/dark | I13: Resumo principal domina; métricas secundárias agrupadas; status usam tokens semânticos; CTAs fixos/roláveis não competem. | J13: C:\Users\luizg\Documents\7Agents\Claude Design\SignallQ Design System — SpeedFlow result + theme.js | N13: =IF(L13="","",ROUND(L13*'00_Leia_Primeiro'!$B$15/'00_Leia_Primeiro'!$B$13,0)) | O13: =IF(M13="","",ROUND(M13*'00_Leia_Primeiro'!$B$16/'00_Leia_Primeiro'!$B$14,0)) | Q13: Screenshot + logcat do período | R13: Bloqueado | T13: Depende de SPD-007; impossível sem resultado real.
A14: 10 | B14: SPD-010 | C14: Resultado de velocidade | D14: Ver recomendações abre Laudo | E14: Navegação | F14: P0 | G14: Resultado aberto | H14: 1. Tocar em Ver recomendações para melhorar 2. Validar destino 3. Voltar | I14: Abre LaudoScreen, sem chat; back retorna ao resultado. | J14: Commit 0683f70 — CTA orgânico; AppShell Overlay.Laudo | K14: Ver recomendações | L14: 195 | M14: 670 | N14: =IF(L14="","",ROUND(L14*'00_Leia_Primeiro'!$B$15/'00_Leia_Primeiro'!$B$13,0)) | O14: =IF(M14="","",ROUND(M14*'00_Leia_Primeiro'!$B$16/'00_Leia_Primeiro'!$B$14,0)) | P14: text~recomendações|melhorar | Q14: Screenshot + logcat do período | R14: Bloqueado | T14: Depende de SPD-007; impossível sem resultado real.
A15: 11 | B15: SPD-011 | C15: Resultado de velocidade | D15: Refazer teste | E15: Funcional | F15: P0 | G15: Resultado aberto | H15: 1. Tocar Refazer teste 2. Observar fechamento do resultado e nova execução | I15: Inicia nova medição uma única vez, limpa estado visual anterior e preserva histórico antigo. | J15: ResultadoVelocidadeScreen | K15: Refazer teste | L15: 195 | M15: 748 | N15: =IF(L15="","",ROUND(L15*'00_Leia_Primeiro'!$B$15/'00_Leia_Primeiro'!$B$13,0)) | O15: =IF(M15="","",ROUND(M15*'00_Leia_Primeiro'!$B$16/'00_Leia_Primeiro'!$B$14,0)) | P15: text~Refazer | Q15: Screenshot + logcat do período | R15: Bloqueado | T15: Depende de SPD-007; impossível sem resultado real.
A16: 12 | B16: SPD-012 | C16: Resultado de velocidade | D16: Compartilhar PDF | E16: Funcional | F16: P0 | G16: Resultado real concluído | H16: 1. Tocar Compartilhar 2. Aguardar geração 3. Validar Android Sharesheet e arquivo | I16: PDF/arquivo é gerado com dados do teste, abre sharesheet e evento speedtest_compartilhou só ocorre após geração real. | J16: ResultadoPdfGenerator + commit 946d0513 | K16: Compartilhar | L16: 360 | M16: 52 | N16: =IF(L16="","",ROUND(L16*'00_Leia_Primeiro'!$B$15/'00_Leia_Primeiro'!$B$13,0)) | O16: =IF(M16="","",ROUND(M16*'00_Leia_Primeiro'!$B$16/'00_Leia_Primeiro'!$B$14,0)) | P16: contentDescription~Compartilhar | Q16: Screenshot + logcat do período | R16: Bloqueado | T16: Depende de SPD-007; geração de PDF requer resultado real.
A17: 13 | B17: SPD-013 | C17: Resultado de velocidade | D17: Persistência no Histórico | E17: Funcional | F17: P0 | G17: Teste concluído | H17: 1. Anotar valores 2. Voltar e abrir Histórico 3. Abrir detalhe da entrada mais recente | I17: Existe exatamente uma nova entrada com mesmos valores, conexão, operadora e horário. | J17: SpeedtestPersistenceCoordinator + Room | N17: =IF(L17="","",ROUND(L17*'00_Leia_Primeiro'!$B$15/'00_Leia_Primeiro'!$B$13,0)) | O17: =IF(M17="","",ROUND(M17*'00_Leia_Primeiro'!$B$16/'00_Leia_Primeiro'!$B$14,0)) | Q17: Screenshot + logcat do período | R17: Bloqueado | T17: Depende de SPD-007; requer teste real persistido.
A18: 14 | B18: SPD-014 | C18: Velocidade | D18: Último resultado no idle | E18: Funcional | F18: P1 | G18: Ao menos um teste persistido | H18: 1. Fechar resultado 2. Voltar para aba Velocidade 3. Comparar card Último resultado | I18: Card mostra o teste mais recente, com link/ação coerente; anúncio, se habilitado, não quebra layout. | J18: Commit 0683f70 — NativeAdRow após último resultado | N18: =IF(L18="","",ROUND(L18*'00_Leia_Primeiro'!$B$15/'00_Leia_Primeiro'!$B$13,0)) | O18: =IF(M18="","",ROUND(M18*'00_Leia_Primeiro'!$B$16/'00_Leia_Primeiro'!$B$14,0)) | Q18: Screenshot + logcat do período | R18: Bloqueado | T18: Depende de SPD-007; requer resultado anterior em cache.
A19: 15 | B19: SPD-015 | C19: Velocidade | D19: Rede móvel pede confirmação | E19: Funcional | F19: P0 | G19: Conexão ativa móvel/metered; modo completo | H19: 1. Tocar iniciar 2. Ler aviso de consumo 3. Cancelar 4. Repetir e confirmar | I19: Aviso aparece uma vez antes do teste pesado; cancelar não inicia; confirmar inicia; não há loop. | J19: AppShell — ForaDoWifiDialog + deveSolicitarConfirmacaoRedeMovel | N19: =IF(L19="","",ROUND(L19*'00_Leia_Primeiro'!$B$15/'00_Leia_Primeiro'!$B$13,0)) | O19: =IF(M19="","",ROUND(M19*'00_Leia_Primeiro'!$B$16/'00_Leia_Primeiro'!$B$14,0)) | Q19: Screenshot + logcat do período | R19: Realizar em device real | T19: Requer SIM fisico / rede movel real
A20: 16 | B20: SPD-016 | C20: Velocidade | D20: Modo rápido em rede móvel | E20: Funcional | F20: P1 | G20: Conexão móvel | H20: 1. Selecionar modo rápido, se disponível 2. Iniciar | I20: Comportamento segue regra do código; confirmação não é exibida indevidamente para modo que não exige carga pesada. | J20: deveSolicitarConfirmacaoRedeMovel | N20: =IF(L20="","",ROUND(L20*'00_Leia_Primeiro'!$B$15/'00_Leia_Primeiro'!$B$13,0)) | O20: =IF(M20="","",ROUND(M20*'00_Leia_Primeiro'!$B$16/'00_Leia_Primeiro'!$B$14,0)) | Q20: Screenshot + logcat do período | R20: Realizar em device real | T20: Requer rede movel real
A21: 17 | B21: SPD-017 | C21: Velocidade | D21: Sem internet | E21: Erro | F21: P0 | G21: Sem internet | H21: 1. Tentar iniciar 2. Aguardar timeout/erro 3. Ler mensagem 4. Tentar novamente após restaurar rede | I21: Erro é claro, não trava, permite voltar/tentar novamente; não cria medição falsa. | J21: ExecutorSpeedtestCloudflare + estado erro | N21: =IF(L21="","",ROUND(L21*'00_Leia_Primeiro'!$B$15/'00_Leia_Primeiro'!$B$13,0)) | O21: =IF(M21="","",ROUND(M21*'00_Leia_Primeiro'!$B$16/'00_Leia_Primeiro'!$B$14,0)) | Q21: Screenshot + logcat do período | R21: Bloqueado | T21: Requer desativação de rede Wi-Fi/móvel no emulador; nao pode fazer via adb simples.
A22: 18 | B22: SPD-018 | C22: Velocidade | D22: Back na tela de erro | E22: Navegação | F22: P0 | G22: Speedtest em estado erro | H22: 1. Pressionar back físico/gesto | I22: Descarta estado de erro/cancela e volta ao idle; não fecha o app. | J22: AppShell.kt — BackHandler estado erro | N22: =IF(L22="","",ROUND(L22*'00_Leia_Primeiro'!$B$15/'00_Leia_Primeiro'!$B$13,0)) | O22: =IF(M22="","",ROUND(M22*'00_Leia_Primeiro'!$B$16/'00_Leia_Primeiro'!$B$14,0)) | Q22: Screenshot + logcat do período | R22: Bloqueado | T22: Depende de SPD-017 (tela de erro); impossível sem cenário anterior.
A23: 19 | B23: SPD-019 | C23: Velocidade | D23: Duplo toque no CTA | E23: Confiabilidade | F23: P1 | G23: Tela idle | H23: 1. Tocar duas vezes rapidamente no CTA 2. Observar logs e UI | I23: Apenas uma execução e uma sessão são criadas; sem sobreposição de progresso. | J23: SpeedtestViewModel | N23: =IF(L23="","",ROUND(L23*'00_Leia_Primeiro'!$B$15/'00_Leia_Primeiro'!$B$13,0)) | O23: =IF(M23="","",ROUND(M23*'00_Leia_Primeiro'!$B$16/'00_Leia_Primeiro'!$B$14,0)) | Q23: Screenshot + logcat do período | R23: Bloqueado | T23: CTA nao encontrado
A24: 20 | B24: SPD-020 | C24: Velocidade | D24: Background/foreground durante teste | E24: Confiabilidade | F24: P1 | G24: Teste executando | H24: 1. Enviar app para background por 5 s 2. Retornar 3. Aguardar conclusão | I24: Estado continua coerente ou cancela de forma explícita; sem crash, ANR ou resultado duplicado. | J24: Lifecycle + StateFlow | N24: =IF(L24="","",ROUND(L24*'00_Leia_Primeiro'!$B$15/'00_Leia_Primeiro'!$B$13,0)) | O24: =IF(M24="","",ROUND(M24*'00_Leia_Primeiro'!$B$16/'00_Leia_Primeiro'!$B$14,0)) | Q24: Screenshot + logcat do período | R24: Bloqueado | T24: Requer teste em background; emulador instável com foreground/background rápido.
A25: 21 | B25: SPD-021 | C25: Resultado de velocidade | D25: Banner/disclaimer Anatel | E25: Design | F25: P1 | G25: Resultado aberto | H25: 1. Rolar até o rodapé 2. Inspecionar disclaimer e CTA fixo | I25: Disclaimer legível, não encobre conteúdo/CTA e respeita insets. | J25: Commit 0683f70 — barra fixa/Anatel | N25: =IF(L25="","",ROUND(L25*'00_Leia_Primeiro'!$B$15/'00_Leia_Primeiro'!$B$13,0)) | O25: =IF(M25="","",ROUND(M25*'00_Leia_Primeiro'!$B$16/'00_Leia_Primeiro'!$B$14,0)) | Q25: Screenshot + logcat do período | R25: Bloqueado | T25: Depende de SPD-007; impossível sem resultado real.
A26: 22 | B26: SPD-022 | C26: Resultado de velocidade | D26: Anúncio nativo quando habilitado | E26: Design | F26: P2 | G26: Ads habilitados e inventário disponível | H26: 1. Rolar até o fim 2. Aguardar anúncio 3. Testar ausência de inventário | I26: Anúncio aparece somente no slot previsto, identificado, sem competir com CTA; ausência não deixa buraco quebrado. | J26: Commit 0683f70 — AdSlot | N26: =IF(L26="","",ROUND(L26*'00_Leia_Primeiro'!$B$15/'00_Leia_Primeiro'!$B$13,0)) | O26: =IF(M26="","",ROUND(M26*'00_Leia_Primeiro'!$B$16/'00_Leia_Primeiro'!$B$14,0)) | Q26: Screenshot + logcat do período | R26: Bloqueado | T26: Depende de SPD-007; AdMob/anúncio nativo requer resultado real e config de rede.
A27: 23 | B27: SPD-023 | C27: Velocidade | D27: Logs do funil | E27: Logs | F27: P1 | G27: Executar iniciar→concluir→compartilhar | H27: 1. Filtrar log/analytics 2. Verificar ordem e quantidade | I27: Eventos abriu, speedtest_iniciado, speedtest_completou e speedtest_compartilhou aparecem uma vez, na ordem, correlacionáveis. | J27: Commit 946d0513 | N27: =IF(L27="","",ROUND(L27*'00_Leia_Primeiro'!$B$15/'00_Leia_Primeiro'!$B$13,0)) | O27: =IF(M27="","",ROUND(M27*'00_Leia_Primeiro'!$B$16/'00_Leia_Primeiro'!$B$14,0)) | Q27: Screenshot + logcat do período | R27: Falhou | T27: Tentei validar logcat, mas nao consigo iniciar teste real (mesmo motivo que SPD-007). Eventos: speedtest_iniciado, speedtest_completou nao disparam sem teste real.
A28: 24 | B28: SPD-024 | C28: Velocidade | D28: Sem ANR e responsividade | E28: Performance | F28: P0 | G28: Teste completo | H28: 1. Durante execução, interagir com cancelar e sistema 2. Monitorar frames/logs 3. Aguardar 2 testes seguidos | I28: UI permanece responsiva, sem ANR/FATAL; memória não cresce de forma evidente entre execuções. | J28: Crashlytics/Android vitals | N28: =IF(L28="","",ROUND(L28*'00_Leia_Primeiro'!$B$15/'00_Leia_Primeiro'!$B$13,0)) | O28: =IF(M28="","",ROUND(M28*'00_Leia_Primeiro'!$B$16/'00_Leia_Primeiro'!$B$14,0)) | Q28: Screenshot + logcat do período | R28: Bloqueado | T28: Requer multiplas execucoes de teste em sequencia; impossível sem rede real.

Sheet 05_Sinal
A1: Sinal Wi-Fi, canais, móvel e topologia
A2: Execute em ordem. Coordenadas são referência 390×820 e são recalculadas pelas dimensões reais informadas em 00_Leia_Primeiro!B15:B16. Use seletor semântico antes de tap por coordenada.
A4: Ordem | B4: ID | C4: Tela / componente | D4: Estado / cenário | E4: Categoria | F4: Prioridade | G4: Pré-condições | H4: Passo a passo | I4: Resultado esperado | J4: Referência design / código | K4: Ação / alvo | L4: X base 390 | M4: Y base 820 | N4: X device | O4: Y device | P4: Seletor preferencial | Q4: Evidência esperada | R4: Status | S4: Issue GitHub (#) | T4: Observações | U4: Bloqueador / dependência
